Workbook

Sheet Target List
A1: Tier | B1: Company | C1: Website | D1: HQ / Location | E1: Founded | F1: Yrs | G1: Emp (low) | H1: Emp (high) | I1: Employee source | J1: Est. rev low ($M) | K1: Est. rev high ($M) | L1: Est. sale price low ($M) | M1: Est. sale price high ($M) | N1: 3rd-party rev est. | O1: Ownership | P1: Owner / principal | Q1: Sale signal | R1: Signal basis (inference unless noted) | S1: Clients (stated) | T1: Services focus | U1: Rating (reviews) | V1: Notes / data conflicts
A2: A | B2: ICC — Integrated Computer Consulting | C2: =HYPERLINK("https://www.iccusa.net","www.iccusa.net") -> www.iccusa.net | D2: Fort Collins | E2: 1998 | F2: =IF(E2="","",Method!$B$2-E2) -> 28 | G2: 26 | H2: 26 | I2: Verified direct count of team page | J2: =IF(G2="","",ROUND(G2*Method!$B$3/1000000,1)) -> 3.9 | K2: =IF(H2="","",ROUND(H2*Method!$B$4/1000000,1)) -> 5.2 | L2: =IF(J2="","",ROUND(J2*Method!$B$6*Method!$B$7,1)) -> 2.3 | M2: =IF(K2="","",ROUND(K2*Method!$B$6*Method!$B$8,1)) -> 5.5 | O2: Owner-operated, independent | P2: Kirk Bane (President & CEO) | Q2: High | R2: 28-yr firm, same CEO; unusually deep VP bench (3 sales VPs + VP Fin + VP Ops) suggests either professionalizing or prepping to sell | S2: 160+ clients (verified) | T2: MSP + cybersecurity; dental, mfg, healthcare, legal, accounting; 10-50 employee target clients in CO/WY | U2: 5.0 (17-23 reviews) | V2: Strongest inference-based target in Northern Colorado
A3: A | B3: InfiNet Computer Solutions | C3: =HYPERLINK("https://infinetinc.com","infinetinc.com") -> infinetinc.com | D3: Fort Collins | E3: 1998 | F3: =IF(E3="","",Method!$B$2-E3) -> 28 | G3: 8 | H3: 15 | I3: Directory <25; self-described small team | J3: =IF(G3="","",ROUND(G3*Method!$B$3/1000000,1)) -> 1.2 | K3: =IF(H3="","",ROUND(H3*Method!$B$4/1000000,1)) -> 3 | L3: =IF(J3="","",ROUND(J3*Method!$B$6*Method!$B$7,1)) -> 0.7 | M3: =IF(K3="","",ROUND(K3*Method!$B$6*Method!$B$8,1)) -> 3.2 | O3: Owner-operated | P3: Tad Osborn (President) — "same ownership since 1998" per directory language | Q3: High | R3: 28 unbroken years under one president; marketing leans on longevity/retention not growth; unmodernized service mix (web hosting, domain registration) = low reinvestment | S3: Two-decade client tenures cited | T3: MSP + cybersecurity, server admin, web hosting/design, database consulting, VPS — legacy-era service sprawl | V3: Strongest EXPLICIT succession signal found; verify headcount vs floor
A4: A | B4: Pro-IS (Professional Information Services) | C4: =HYPERLINK("https://pro-is.com","pro-is.com") -> pro-is.com | D4: Fort Collins | E4: 1998 | F4: =IF(E4="","",Method!$B$2-E4) -> 28 | G4: 10 | H4: 20 | I4: Unverified — absent from Clutch FC table; est. only | J4: =IF(G4="","",ROUND(G4*Method!$B$3/1000000,1)) -> 1.5 | K4: =IF(H4="","",ROUND(H4*Method!$B$4/1000000,1)) -> 4 | L4: =IF(J4="","",ROUND(J4*Method!$B$6*Method!$B$7,1)) -> 0.9 | M4: =IF(K4="","",ROUND(K4*Method!$B$6*Method!$B$8,1)) -> 4.2 | O4: Owner-operated | P4: Josh Orrison (Owner & CEO, Forbes Technology Council) | Q4: Moderate | R4: 28-yr firm, single named owner, notably under-documented publicly — high information-asymmetry opportunity | T4: General MSP; positions toward mid-large CO businesses | V4: Priority direct-outreach target precisely because so little is public
A5: A | B5: DCNC, Inc. | D5: Denver (N Broadway) | E5: 1998 | F5: =IF(E5="","",Method!$B$2-E5) -> 28 | G5: 13 | H5: 13 | I5: MSP Companies directory | J5: =IF(G5="","",ROUND(G5*Method!$B$3/1000000,1)) -> 2 | K5: =IF(H5="","",ROUND(H5*Method!$B$4/1000000,1)) -> 2.6 | L5: =IF(J5="","",ROUND(J5*Method!$B$6*Method!$B$7,1)) -> 1.2 | M5: =IF(K5="","",ROUND(K5*Method!$B$6*Method!$B$8,1)) -> 2.7 | O5: Owner-operated, privately held | P5: John C. Hardon (President); Derek Burnham (VP) | Q5: High | R5: 28 years, oldest independent owner-operated firm in core Denver dataset; small stable headcount, unchanged two-person leadership — textbook succession-risk profile | T5: General MSP — outsourced IT, cybersecurity, cloud, networking, software dev, backup/DR | U5: 32 reviews (Birdeye) | V5: No confirmed website domain found; verify via BBB/LinkedIn
A6: A | B6: Business Network Consulting (BNC) | C6: =HYPERLINK("https://www.bncsystems.com","www.bncsystems.com") -> www.bncsystems.com | D6: Denver | E6: 1997 | F6: =IF(E6="","",Method!$B$2-E6) -> 29 | G6: 20 | H6: 40 | I6: Clutch 10-49; DesignRush <49 — wide band | J6: =IF(G6="","",ROUND(G6*Method!$B$3/1000000,1)) -> 3 | K6: =IF(H6="","",ROUND(H6*Method!$B$4/1000000,1)) -> 8 | L6: =IF(J6="","",ROUND(J6*Method!$B$6*Method!$B$7,1)) -> 1.8 | M6: =IF(K6="","",ROUND(K6*Method!$B$6*Method!$B$8,1)) -> 8.4 | O6: Owner-operated, founder-led | P6: Joe Kelly (CEO & Founder) | Q6: High | R6: 29 years, ORIGINAL FOUNDER still sitting CEO — one of the strongest founder-tenure signals in Denver; multi-state footprint built by acquisition (TX 2007) makes it a plausible platform sale | T6: IT outsourcing, cloud/M365, cybersecurity/compliance, staff aug, 24/7 helpdesk, AI consulting; Denver/Dallas/Austin/Ft Lauderdale | U6: 5.0 (2 Clutch); 5.0 (16 DesignRush) | V6: 'Top 100 privately-held CO companies' claim unverified
A7: A | B7: GrahamGolden Technologies | C7: =HYPERLINK("https://www.grahamgoldentech.com","www.grahamgoldentech.com") -> www.grahamgoldentech.com | D7: Denver | E7: 2001 | F7: =IF(E7="","",Method!$B$2-E7) -> 25 | G7: 12 | H7: 12 | I7: RocketReach (Oct 2025), incl. offshore staff | J7: =IF(G7="","",ROUND(G7*Method!$B$3/1000000,1)) -> 1.8 | K7: =IF(H7="","",ROUND(H7*Method!$B$4/1000000,1)) -> 2.4 | L7: =IF(J7="","",ROUND(J7*Method!$B$6*Method!$B$7,1)) -> 1.1 | M7: =IF(K7="","",ROUND(K7*Method!$B$6*Method!$B$8,1)) -> 2.5 | O7: Owner-operated, two-partner | P7: Ralph Graham & Jeremy Golden (co-founding partners) | Q7: High | R7: 25 yrs, BOTH original founders still in seat; cited '35 combined years experience' at founding implies an older founder cohort now | S7: Named clients: Chipotle, SmartWool, Vail Resorts | T7: Network/server design & support, virtualization, VoIP; SMB + enterprise | V7: Offshore component may lower true rev/employee
A8: A | B8: Anchor Network Solutions | C8: =HYPERLINK("https://www.anchornetworksolutions.com","www.anchornetworksolutions.com") -> www.anchornetworksolutions.com | D8: Englewood (DTC/Inverness) | E8: 2002 | F8: =IF(E8="","",Method!$B$2-E8) -> 24 | G8: 10 | H8: 30 | I8: ~30 staff per directory sweep; company site headcount not disclosed — verify | J8: =IF(G8="","",ROUND(G8*Method!$B$3/1000000,1)) -> 1.5 | K8: =IF(H8="","",ROUND(H8*Method!$B$4/1000000,1)) -> 6 | L8: =IF(J8="","",ROUND(J8*Method!$B$6*Method!$B$7,1)) -> 0.9 | M8: =IF(K8="","",ROUND(K8*Method!$B$6*Method!$B$8,1)) -> 6.3 | O8: Owner-operated | P8: Vince Tinnirello (founder, Managing Director) | Q8: Moderate | R8: 24 yrs, founder still principal but title is 'Managing Director' not CEO, plus a LinkedIn 'Business Development' descriptor — may indicate step-back from day-to-day ops (inference from title only) | T8: IT consulting, strategic technology advisory, systems maintenance; Denver metro + NW Kansas | U8: 4.9 (77 Google) | V8: Founder active in MSP-Ignite peer-coaching group; published author/speaker
A9: A | B9: Computer Concepts Inc. (CCI) | C9: =HYPERLINK("https://www.computerci.com","www.computerci.com") -> www.computerci.com | D9: Denver | E9: 1991 | F9: =IF(E9="","",Method!$B$2-E9) -> 35 | G9: 15 | H9: 30 | I9: DesignRush band 50-99 conflicts sharply with stated footprint (20+ clients) — LOW CONFIDENCE, use with caution | J9: =IF(G9="","",ROUND(G9*Method!$B$3/1000000,1)) -> 2.3 | K9: =IF(H9="","",ROUND(H9*Method!$B$4/1000000,1)) -> 6 | L9: =IF(J9="","",ROUND(J9*Method!$B$6*Method!$B$7,1)) -> 1.4 | M9: =IF(K9="","",ROUND(K9*Method!$B$6*Method!$B$8,1)) -> 6.3 | O9: Privately held; owner not publicly named | P9: Unknown — not found anywhere in company materials | Q9: High | R9: 35 years — the longest-operating firm in the Denver dataset; owner identity itself unidentified, unusual for a firm this old; small high-value regulated client base is a strong structural succession candidate | S9: 20+ organizations, 15+ countries; 3,456 managed endpoints (verified) | T9: MSP for regulated industries — healthcare EHR/PACS, financial, insurance, legal; HIPAA/SOX/NIST/CIS compliance | V9: Headcount band unreliable — verify before using
A10: A | B10: Colorado Computer Support (CCS / CCS IT Pros) | C10: =HYPERLINK("https://coloradosupport.com","coloradosupport.com") -> coloradosupport.com | D10: Colorado Springs | E10: 2001 | F10: =IF(E10="","",Method!$B$2-E10) -> 25 | G10: 29 | H10: 29 | I10: Tracxn (Jul 2026); LinkedIn 11-50 | J10: =IF(G10="","",ROUND(G10*Method!$B$3/1000000,1)) -> 4.4 | K10: =IF(H10="","",ROUND(H10*Method!$B$4/1000000,1)) -> 5.8 | L10: =IF(J10="","",ROUND(J10*Method!$B$6*Method!$B$7,1)) -> 2.6 | M10: =IF(K10="","",ROUND(K10*Method!$B$6*Method!$B$8,1)) -> 6.1 | O10: Owner-operated, independent | P10: Blake Schwank (Founder & CEO) | Q10: High | R10: 25 yrs founder-led; SDVOSB certification is a transferable, acquisition-attractive credential | T10: Strategic IT, help desk, Apple/Mac support, virtualization; DEDICATED Defense Industrial Base practice — DFARS/NIST 800-171/CMMC readiness for Space Force/Peterson/Schriever contractors | V10: STRONGEST true-MSP defense/CMMC capability in Colorado Springs; do not confuse with 'Custom Computer Specialists' (Hauppauge NY, PE-owned, different company)
A11: A | B11: Amnet Inc. | C11: =HYPERLINK("https://www.amnet.net","www.amnet.net") -> www.amnet.net | D11: Colorado Springs (+ Denver office) | E11: 1998 | F11: =IF(E11="","",Method!$B$2-E11) -> 28 | G11: 40 | H11: 50 | I11: ZoomInfo 46, Jul 2026 — LinkedIn bands conflict 11-50 vs 51-200 | J11: =IF(G11="","",ROUND(G11*Method!$B$3/1000000,1)) -> 6 | K11: =IF(H11="","",ROUND(H11*Method!$B$4/1000000,1)) -> 10 | L11: =IF(J11="","",ROUND(J11*Method!$B$6*Method!$B$7,1)) -> 3.6 | M11: =IF(K11="","",ROUND(K11*Method!$B$6*Method!$B$8,1)) -> 10.5 | N11: ZoomInfo $89.2M is IMPLAUSIBLE (~$1.9M/employee) — disregard | O11: Owner-operated, founder-led, independent | P11: Trevor Dierdorff (Founder & CEO) | Q11: Moderate | R11: 28 yrs founder-led | T11: Managed IT, cybersecurity, cloud, backup; CJIS + HIPAA certified — local government/law-enforcement niche | U11: 4.9 (58 Google) | V11: Do not confuse with 'Amnet Systems LLC' of Stamford CT (acquired by Omega Systems/Pfingsten) — different company
A12: A | B12: TekMyBiz | C12: =HYPERLINK("https://tekmybiz.com","tekmybiz.com") -> tekmybiz.com | D12: Colorado Springs | E12: 1993 | F12: =IF(E12="","",Method!$B$2-E12) -> 33 | G12: 11 | H12: 11 | I12: ZoomInfo/LeadIQ, Jun 2025 | J12: =IF(G12="","",ROUND(G12*Method!$B$3/1000000,1)) -> 1.7 | K12: =IF(H12="","",ROUND(H12*Method!$B$4/1000000,1)) -> 2.2 | L12: =IF(J12="","",ROUND(J12*Method!$B$6*Method!$B$7,1)) -> 1 | M12: =IF(K12="","",ROUND(K12*Method!$B$6*Method!$B$8,1)) -> 2.3 | O12: Owner-operated, independent | P12: Mike Molsen (founder) | Q12: High | R12: 32+ years under the SAME NAMED FOUNDER, still personally identified with the brand — strongest age-based inference in the Colorado Springs dataset | T12: Managed IT, cybersecurity/compliance, cloud/WVD, backup, VoIP, MDM; small-business generalist | V12: Second office in Elk Grove Village IL
A13: A | B13: Springs Hosting | C13: =HYPERLINK("https://www.springshosting.com","www.springshosting.com") -> www.springshosting.com | D13: Colorado Springs | E13: 2006 | F13: =IF(E13="","",Method!$B$2-E13) -> 20 | G13: 11 | H13: 25 | I13: LinkedIn band 11-50 | J13: =IF(G13="","",ROUND(G13*Method!$B$3/1000000,1)) -> 1.7 | K13: =IF(H13="","",ROUND(H13*Method!$B$4/1000000,1)) -> 5 | L13: =IF(J13="","",ROUND(J13*Method!$B$6*Method!$B$7,1)) -> 1 | M13: =IF(K13="","",ROUND(K13*Method!$B$6*Method!$B$8,1)) -> 5.3 | N13: $11.1M (ZoomInfo/Datanyze-class est.) — plausible only if data-center revenue included | O13: Owner-operated, independent | P13: Don Brown (Founder, Owner & CEO) | Q13: Moderate | R13: 20 yrs founder-led; non-founder CIO (Jeremy Keefe) brought in ~5 yrs ago — professionalization pattern often precedes a sale | T13: Managed IT + OWNS physical data center — colocation, dedicated servers, web/email hosting, VoIP, DR; SSAE16/HIPAA/PCI/UL827 | V13: Rare asset profile: real estate + infra, not a pure MSP — different buyer calculus
A14: A | B14: Networks Unlimited, Inc. | C14: =HYPERLINK("https://networksunlimited.com","networksunlimited.com") -> networksunlimited.com | D14: Grand Junction (+ Montrose, Casper WY) | E14: 2001 | F14: =IF(E14="","",Method!$B$2-E14) -> 25 | G14: 35 | H14: 40 | I14: Company statement: grew from 2 to 35+ | J14: =IF(G14="","",ROUND(G14*Method!$B$3/1000000,1)) -> 5.3 | K14: =IF(H14="","",ROUND(H14*Method!$B$4/1000000,1)) -> 8 | L14: =IF(J14="","",ROUND(J14*Method!$B$6*Method!$B$7,1)) -> 3.2 | M14: =IF(K14="","",ROUND(K14*Method!$B$6*Method!$B$8,1)) -> 8.4 | O14: Owner-operated, independent | P14: Mark Swain (owner/founder) | Q14: Low | R14: ITSELF AN ACTIVE ACQUIRER — bought 307 Tech Pros (Casper WY) Sep 2025; behavior of a consolidator, not a seller | T14: Managed IT, cloud/productivity, cybersecurity/compliance, infrastructure, VoIP; healthcare + regional SMB verticals | V14: MSP 501, Inc. 5000, Colorado Companies to Watch — largest independent Western Slope MSP; watch as a RIVAL BUYER, not just a target
A15: A | B15: Bell Tech Pros | C15: =HYPERLINK("https://belltechpros.com","belltechpros.com") -> belltechpros.com | D15: Montrose (+ Grand Junction, Denver, Phoenix) | G15: 8 | H15: 15 | I15: Unverified — est. only | J15: =IF(G15="","",ROUND(G15*Method!$B$3/1000000,1)) -> 1.2 | K15: =IF(H15="","",ROUND(H15*Method!$B$4/1000000,1)) -> 3 | L15: =IF(J15="","",ROUND(J15*Method!$B$6*Method!$B$7,1)) -> 0.7 | M15: =IF(K15="","",ROUND(K15*Method!$B$6*Method!$B$8,1)) -> 3.2 | O15: Owner-operated, independent | P15: Joel Bell (owner) | Q15: Moderate | R15: 25+ yrs owner-operated; eponymous brand tied to owner's surname — complicates but also signals founder-identity business | S15: 1,000+ CO businesses served (cumulative marketing claim, not current MRR count) | T15: MSP, managed security/cloud, VoIP; UNUSUALLY heavy physical security/low-voltage mix — cameras, access control, building security | V15: Diversified revenue base beyond pure MSP
A16: A | B16: Mitchell and Company | C16: =HYPERLINK("https://mitchandco.com","mitchandco.com") -> mitchandco.com | D16: Carbondale + Edwards | E16: 1996 | F16: =IF(E16="","",Method!$B$2-E16) -> 30 | G16: 5 | H16: 15 | I16: Unverified — est. only | J16: =IF(G16="","",ROUND(G16*Method!$B$3/1000000,1)) -> 0.8 | K16: =IF(H16="","",ROUND(H16*Method!$B$4/1000000,1)) -> 3 | L16: =IF(J16="","",ROUND(J16*Method!$B$6*Method!$B$7,1)) -> 0.5 | M16: =IF(K16="","",ROUND(K16*Method!$B$6*Method!$B$8,1)) -> 3.2 | O16: Owner-operated, independent | P16: Not published — firm name implies founder surname Mitchell | Q16: Moderate | R16: 30 years operating, eponymous firm name, very broad but thin multi-market coverage — characteristic of a mature owner-operated lifestyle business | T16: Network technology design, implementation, unified IT infrastructure; exceptionally broad coverage: Aspen to Durango | V16: Public sector clients across Western Colorado
A17: A | B17: Decypher Technologies | C17: =HYPERLINK("https://decyphertech.com","decyphertech.com") -> decyphertech.com | D17: Glenwood Springs (+ Aspen, Vail, Denver, Palm Beach FL) | E17: 2003 | F17: =IF(E17="","",Method!$B$2-E17) -> 23 | G17: 20 | H17: 25 | I17: Directory band 'fewer than 25' | J17: =IF(G17="","",ROUND(G17*Method!$B$3/1000000,1)) -> 3 | K17: =IF(H17="","",ROUND(H17*Method!$B$4/1000000,1)) -> 5 | L17: =IF(J17="","",ROUND(J17*Method!$B$6*Method!$B$7,1)) -> 1.8 | M17: =IF(K17="","",ROUND(K17*Method!$B$6*Method!$B$8,1)) -> 5.3 | O17: Appears independent/private — no PE sponsor found | P17: Farr Shepherd (CEO); Audrey Burgio (COO); Mick Reilly (CTO) | Q17: Verify | R17: No retirement signal found — but the BEST-positioned independent asset in the resort corridor | T17: Managed IT + cybersecurity for luxury residences/family offices/hospitality; Cellular DAS & public-safety comms — genuinely differentiated UHNW niche | V17: Inc. 5000, CRN, multiple cybersecurity awards; highest-quality independent asset in mountain region
A18: A | B18: Northwest Data Services (NDS) | C18: =HYPERLINK("https://northwestdata.com","northwestdata.com") -> northwestdata.com | D18: Steamboat Springs | G18: 10 | H18: 25 | I18: ZoomInfo band 11-50 (a conflicting 100-250 figure is implausible for this market, disregard) | J18: =IF(G18="","",ROUND(G18*Method!$B$3/1000000,1)) -> 1.5 | K18: =IF(H18="","",ROUND(H18*Method!$B$4/1000000,1)) -> 5 | L18: =IF(J18="","",ROUND(J18*Method!$B$6*Method!$B$7,1)) -> 0.9 | M18: =IF(K18="","",ROUND(K18*Method!$B$6*Method!$B$8,1)) -> 5.3 | O18: Appears independent, owner-operated | P18: Jon Quinn (President) | Q18: Verify | R18: No retirement signal found — but the ONLY substantial MSP in Steamboat Springs/Routt County; effective regional incumbent with essentially no local competition | T18: Managed IT, computers/servers/networks/phones/cameras, structured wiring & fiber | V18: Scarcity value is high — white-space market
A19: B | B19: Kenyatta Computer Services (KCS) | C19: =HYPERLINK("https://kcsbus.com","kcsbus.com") -> kcsbus.com | D19: Centennial / DTC | E19: 1990 | F19: =IF(E19="","",Method!$B$2-E19) -> 36 | G19: 40 | H19: 40 | I19: CloudSecureTech company profile | J19: =IF(G19="","",ROUND(G19*Method!$B$3/1000000,1)) -> 6 | K19: =IF(H19="","",ROUND(H19*Method!$B$4/1000000,1)) -> 8 | L19: =IF(J19="","",ROUND(J19*Method!$B$6*Method!$B$7,1)) -> 3.6 | M19: =IF(K19="","",ROUND(K19*Method!$B$6*Method!$B$8,1)) -> 8.4 | O19: Owner-operated, family-held — COMPLETED generational transition | P19: Lionel Maybin (founder, 1990); Nahjee Maybin (current CEO, took over end of 2018) | Q19: Low | R19: Succession ALREADY EXECUTED (2018 handoff) — reduces near-term sale likelihood; founder retired from Air Force 2008 so likely past traditional retirement age but already stepped back | S19: 38+ companies supported across 26 states | T19: MSP, cybersecurity, 24/7 helpdesk, vCIO, structured cabling; one of few minority-owned MSPs in Denver metro | U19: 5.0 (19 verified Google) | V19: Useful comp for a completed family succession
A20: B | B20: TrinWare (Microsel of Colorado LLC) | C20: =HYPERLINK("https://trinware.com","trinware.com") -> trinware.com | D20: Centennial | E20: 2004 | F20: =IF(E20="","",Method!$B$2-E20) -> 22 | G20: 27 | H20: 28 | I20: ZoomInfo/LeadIQ, Jul 2026 | J20: =IF(G20="","",ROUND(G20*Method!$B$3/1000000,1)) -> 4.1 | K20: =IF(H20="","",ROUND(H20*Method!$B$4/1000000,1)) -> 5.6 | L20: =IF(J20="","",ROUND(J20*Method!$B$6*Method!$B$7,1)) -> 2.5 | M20: =IF(K20="","",ROUND(K20*Method!$B$6*Method!$B$8,1)) -> 5.9 | O20: Owner-operated, privately held | P20: Dan Cashman (President); David Dillion (Chief Services Officer); Kristan Anderson (CFO) | Q20: Moderate | R20: 22 yrs, stable long-tenured leadership team | T20: MSP + cybersecurity + CUSTOM HARDWARE MANUFACTURING (simulation, digital signage, esports, CAD); publishes own Denver MSP buyer's guide | V20: Hardware division complicates a clean MSP-only sale
A21: B | B21: eCreek IT Solutions | C21: =HYPERLINK("https://www.ecreekit.com","www.ecreekit.com") -> www.ecreekit.com | D21: Denver | E21: 2004 | F21: =IF(E21="","",Method!$B$2-E21) -> 22 | G21: 15 | H21: 22 | I21: Greenwood Village Chamber: '22 employees in 18 years'; a separate source cites 15 — treat as 15-22 | J21: =IF(G21="","",ROUND(G21*Method!$B$3/1000000,1)) -> 2.3 | K21: =IF(H21="","",ROUND(H21*Method!$B$4/1000000,1)) -> 4.4 | L21: =IF(J21="","",ROUND(J21*Method!$B$6*Method!$B$7,1)) -> 1.4 | M21: =IF(K21="","",ROUND(K21*Method!$B$6*Method!$B$8,1)) -> 4.6 | O21: Owner-operated / independent, self-described locally owned | P21: Scott Larson (founder, ex-Dish Network) | Q21: Moderate | R21: 22 yrs; founder had a prior full career at Dish Network before founding, implying an older founder cohort; Inc 5000 growth firms are also common sale candidates | S21: Targets orgs with 10-500 workstations | T21: Co-managed IT, cybersecurity, compliance (HIPAA/CMMC/SOC2), VoIP; Denver/Boulder/DTC/Colo Springs/Golden/Superior | U21: 4.9 (80 Google); Inc. 5000 2025 (#3,485), 3 yrs running | V21: 112% 3-yr growth per Inc. 5000
A22: A | B22: Office Automation Technologies, Inc. (OATI) | C22: =HYPERLINK("https://oati1.com","oati1.com") -> oati1.com | D22: Wheat Ridge | E22: 1994 | F22: =IF(E22="","",Method!$B$2-E22) -> 32 | G22: 10 | H22: 49 | I22: ZoomInfo band 10-49 | J22: =IF(G22="","",ROUND(G22*Method!$B$3/1000000,1)) -> 1.5 | K22: =IF(H22="","",ROUND(H22*Method!$B$4/1000000,1)) -> 9.8 | L22: =IF(J22="","",ROUND(J22*Method!$B$6*Method!$B$7,1)) -> 0.9 | M22: =IF(K22="","",ROUND(K22*Method!$B$6*Method!$B$8,1)) -> 10.3 | O22: Independent; contact listed as David Wacker (title unconfirmed as owner) | P22: David Wacker (contact; ownership unverified) | Q22: Moderate | R22: 31 yrs; no succession/next-gen leadership mentioned anywhere found — classic aging-owner profile by tenure alone | T22: Managed IT, network monitoring, cybersecurity, cloud, desktop/server support; architectural/engineering/financial verticals | U22: 5.0 (7, Chamber)
A23: A | B23: North Star, Inc. | C23: =HYPERLINK("https://www.nssit.com","www.nssit.com") -> www.nssit.com | D23: Denver | E23: 1992 | F23: =IF(E23="","",Method!$B$2-E23) -> 34 | G23: 5 | H23: 15 | I23: One aggregator says 5 (likely understated for a 30+ yr firm) — verify | J23: =IF(G23="","",ROUND(G23*Method!$B$3/1000000,1)) -> 0.8 | K23: =IF(H23="","",ROUND(H23*Method!$B$4/1000000,1)) -> 3 | L23: =IF(J23="","",ROUND(J23*Method!$B$6*Method!$B$7,1)) -> 0.5 | M23: =IF(K23="","",ROUND(K23*Method!$B$6*Method!$B$8,1)) -> 3.2 | O23: Independent, three co-owners | P23: Darryl Kalli, Brad Miles, Tony Quijano (co-owners, 'hands-on' ownership) | Q23: Moderate | R23: 33 yrs; multi-owner structure with no stated succession plan — could signal eventual generational/exit planning need | T23: Network support, cloud management, IT support/consulting | V23: Name collisions with other 'North Star' firms on Glassdoor/Indeed complicated verification
A24: B | B24: K3 Technology | C24: =HYPERLINK("https://k3techs.com","k3techs.com") -> k3techs.com | D24: Greenwood Village (+ Dallas) | E24: 2017 | F24: =IF(E24="","",Method!$B$2-E24) -> 9 | G24: 27 | H24: 27 | I24: RocketReach/LinkedIn-derived | J24: =IF(G24="","",ROUND(G24*Method!$B$3/1000000,1)) -> 4.1 | K24: =IF(H24="","",ROUND(H24*Method!$B$4/1000000,1)) -> 5.4 | L24: =IF(J24="","",ROUND(J24*Method!$B$6*Method!$B$7,1)) -> 2.5 | M24: =IF(K24="","",ROUND(K24*Method!$B$6*Method!$B$8,1)) -> 5.7 | O24: Independent; owner/founder not confirmed (Jerry Kukuchka is CFO, not confirmed owner) | P24: Unknown | Q24: Low | R24: Young company (2017) — no retirement signal found | T24: Managed IT, cybersecurity, M365, practical AI automation for growing businesses; serves Golden/Brighton via location pages | U24: ~4.96 (23 Google — 22 five-star, 1 four-star)
A25: B | B25: Lark IT (Lark Information Technology) | C25: =HYPERLINK("https://lark-it.com","lark-it.com") -> lark-it.com | D25: Denver | E25: 2003 | F25: =IF(E25="","",Method!$B$2-E25) -> 23 | G25: 15 | H25: 25 | I25: LinkedIn/Clutch band 11-50 | J25: =IF(G25="","",ROUND(G25*Method!$B$3/1000000,1)) -> 2.3 | K25: =IF(H25="","",ROUND(H25*Method!$B$4/1000000,1)) -> 5 | L25: =IF(J25="","",ROUND(J25*Method!$B$6*Method!$B$7,1)) -> 1.4 | M25: =IF(K25="","",ROUND(K25*Method!$B$6*Method!$B$8,1)) -> 5.3 | O25: Owner-operated, founder-led | P25: Tim Hochman (founding CEO) | Q25: Moderate | R25: 23 yrs, founder still CEO | T25: MSP + DevOps/IT consulting hybrid; vCIO/vCTO services, cybersecurity, systems integration
A26: B | B26: Springs IT | C26: =HYPERLINK("https://springsit.com","springsit.com") -> springsit.com | D26: Colorado Springs | E26: 2015 | F26: =IF(E26="","",Method!$B$2-E26) -> 11 | G26: 5 | H26: 15 | I26: Unverified | J26: =IF(G26="","",ROUND(G26*Method!$B$3/1000000,1)) -> 0.8 | K26: =IF(H26="","",ROUND(H26*Method!$B$4/1000000,1)) -> 3 | L26: =IF(J26="","",ROUND(J26*Method!$B$6*Method!$B$7,1)) -> 0.5 | M26: =IF(K26="","",ROUND(K26*Method!$B$6*Method!$B$8,1)) -> 3.2 | O26: Independent — RECLASSIFIED | P26: Unknown | Q26: N/A | R26: Founded 2015 — current site presents as Microsoft/Azure consulting and custom software development, no longer positions as a managed services provider | T26: Azure & cloud, Modern Work (M365), custom software dev — NOTE: has drifted out of the MSP category | U26: 5.0 (9)
A27: B | B27: RainTech | C27: =HYPERLINK("https://rain.tech","rain.tech") -> rain.tech | D27: Colorado Springs | E27: 2001 | F27: =IF(E27="","",Method!$B$2-E27) -> 25 | G27: 10 | H27: 25 | I27: Unverified — est. only | J27: =IF(G27="","",ROUND(G27*Method!$B$3/1000000,1)) -> 1.5 | K27: =IF(H27="","",ROUND(H27*Method!$B$4/1000000,1)) -> 5 | L27: =IF(J27="","",ROUND(J27*Method!$B$6*Method!$B$7,1)) -> 0.9 | M27: =IF(K27="","",ROUND(K27*Method!$B$6*Method!$B$8,1)) -> 5.3 | O27: Appears independent; no PE found | P27: Not named on about page | Q27: Verify | R27: No signal found | T27: AI services, cybersecurity, infrastructure, cloud, compliance (claims NIST 800-171); FQHC/healthcare/construction/nonprofit/PE verticals | U27: 5.0 (7) | V27: Partial CMMC-adjacent capability (NIST 800-171) without an explicit DIB practice
A28: B | B28: Colorado Hi-Tech Solutions (CHTS) | C28: =HYPERLINK("https://coloradohitechsolutions.com","coloradohitechsolutions.com") -> coloradohitechsolutions.com | D28: Colorado Springs | E28: 1996 | F28: =IF(E28="","",Method!$B$2-E28) -> 30 | G28: 10 | H28: 49 | I28: Clutch/directory band | J28: =IF(G28="","",ROUND(G28*Method!$B$3/1000000,1)) -> 1.5 | K28: =IF(H28="","",ROUND(H28*Method!$B$4/1000000,1)) -> 9.8 | L28: =IF(J28="","",ROUND(J28*Method!$B$6*Method!$B$7,1)) -> 0.9 | M28: =IF(K28="","",ROUND(K28*Method!$B$6*Method!$B$8,1)) -> 10.3 | O28: Independent | P28: Zachary King (per directory) | Q28: Moderate | R28: Three decades serving Colorado Springs commercial sector | T28: Fully + co-managed IT, managed security, VoIP/UC, SD-WAN, low-voltage cabling; extends to Pueblo
A29: B | B29: Technical Framework | C29: =HYPERLINK("https://techframework.com","techframework.com") -> techframework.com | D29: Fort Collins (+ Greeley, Loveland) | E29: 2012 | F29: =IF(E29="","",Method!$B$2-E29) -> 14 | G29: 5 | H29: 10 | I29: Clutch band 2-9 — borderline vs. size floor | J29: =IF(G29="","",ROUND(G29*Method!$B$3/1000000,1)) -> 0.8 | K29: =IF(H29="","",ROUND(H29*Method!$B$4/1000000,1)) -> 2 | L29: =IF(J29="","",ROUND(J29*Method!$B$6*Method!$B$7,1)) -> 0.5 | M29: =IF(K29="","",ROUND(K29*Method!$B$6*Method!$B$8,1)) -> 2.1 | O29: Owner-operated | P29: Al Harris (President) & Allison Robin | Q29: Low | R29: 14 yrs, two active founders — not a retirement-window target | S29: 100+ companies (cumulative claim) | T29: MSP + strong compliance posture — HIPAA/CMMC/ITAR/NIST/PCI/SOC2; construction, real estate, CPA, veterinary, law, dental, engineering verticals | V29: FC Chamber Small Business of the Year 2019; CMMC/ITAR is a genuine differentiator
A30: B | B30: iPoint Technologies | C30: =HYPERLINK("https://ipoint-tech.com","ipoint-tech.com") -> ipoint-tech.com | D30: Fort Collins | E30: 2002 | F30: =IF(E30="","",Method!$B$2-E30) -> 24 | G30: 10 | H30: 20 | I30: Conflicting: one source 10, another 20 | J30: =IF(G30="","",ROUND(G30*Method!$B$3/1000000,1)) -> 1.5 | K30: =IF(H30="","",ROUND(H30*Method!$B$4/1000000,1)) -> 4 | L30: =IF(J30="","",ROUND(J30*Method!$B$6*Method!$B$7,1)) -> 0.9 | M30: =IF(K30="","",ROUND(K30*Method!$B$6*Method!$B$8,1)) -> 4.2 | N30: $2M (reported alongside 20-emp figure) — LOW RELIABILITY | O30: Owner-operated | P30: William Bleich (President) | Q30: Moderate | R30: 24 yrs, single named president — but hybrid IT/web/marketing model makes it a messier acquisition (buying recurring MSP revenue means buying a project-services agency too) | T30: HYBRID — managed IT + website design/management + digital marketing
A31: B | B31: Crown Point Solutions | C31: =HYPERLINK("https://crownpointsolutions.com","crownpointsolutions.com") -> crownpointsolutions.com | D31: Fort Collins (+ Minneapolis-St Paul MN) | E31: 2003 | F31: =IF(E31="","",Method!$B$2-E31) -> 23 | G31: 5 | H31: 15 | I31: Unverified | J31: =IF(G31="","",ROUND(G31*Method!$B$3/1000000,1)) -> 0.8 | K31: =IF(H31="","",ROUND(H31*Method!$B$4/1000000,1)) -> 3 | L31: =IF(J31="","",ROUND(J31*Method!$B$6*Method!$B$7,1)) -> 0.5 | M31: =IF(K31="","",ROUND(K31*Method!$B$6*Method!$B$8,1)) -> 3.2 | O31: Not verified — no PE evidence found | P31: Not located | Q31: Verify | R31: 23 yrs; two-metro CO/MN split is unusual for a firm this size and may indicate an owner relocation — worth a call, insufficient public data | T31: Website design, managed IT, cybersecurity for SMB — hybrid web+IT model
A32: B | B32: Connecting Point (of Greeley) | C32: =HYPERLINK("https://www.cpcolorado.com","www.cpcolorado.com") -> www.cpcolorado.com | D32: Greeley | E32: 1985 | F32: =IF(E32="","",Method!$B$2-E32) -> 41 | G32: 17 | H32: 30 | I32: Verified direct count 17 (team page); RocketReach 26; ZoomInfo 35 | J32: =IF(G32="","",ROUND(G32*Method!$B$3/1000000,1)) -> 2.6 | K32: =IF(H32="","",ROUND(H32*Method!$B$4/1000000,1)) -> 6 | L32: =IF(J32="","",ROUND(J32*Method!$B$6*Method!$B$7,1)) -> 1.6 | M32: =IF(K32="","",ROUND(K32*Method!$B$6*Method!$B$8,1)) -> 6.3 | N32: RocketReach $15M / ZoomInfo $8.5M — likely includes hardware resale, not services-only | O32: Owner-operated, second generation | P32: Ted Warner (founder) → sons Scott Warner (Pres/CEO) & Andy Warner (CFO), 50/50 since Apr 2019 | Q32: Low | R32: Succession ALREADY EXECUTED (2019) to sons then mid-30s (~early 40s now) — opposite of a retirement-window target, but a high-quality asset if the brothers ever entertain an exit | T32: General MSP + cybersecurity, cloud, M365; VAR/hardware-resale heritage; CRN MSP 500/Pioneer 250 2024, MSP 501 | U32: ~5.0 (21+ reviews) | V32: Useful comp: clean 2-owner structure, no PE, 40-yr brand
A33: B | B33: Windward Networks | C33: =HYPERLINK("https://windwardnetworks.com","windwardnetworks.com") -> windwardnetworks.com | D33: Boulder | G33: 5 | H33: 15 | I33: Unverified — est. only | J33: =IF(G33="","",ROUND(G33*Method!$B$3/1000000,1)) -> 0.8 | K33: =IF(H33="","",ROUND(H33*Method!$B$4/1000000,1)) -> 3 | L33: =IF(J33="","",ROUND(J33*Method!$B$6*Method!$B$7,1)) -> 0.5 | M33: =IF(K33="","",ROUND(K33*Method!$B$6*Method!$B$8,1)) -> 3.2 | O33: 'Locally owned and operated' — explicit anti-roll-up positioning | P33: Not publicly named | Q33: Moderate | R33: 20+ yrs; deliberate anti-PE marketing stance cuts both ways — may signal genuine independence, or may be held by an owner who would still sell privately | T33: General MSP; clients 3-100 employees
A34: C | B34: Simplified IT Solutions (simpinc) | C34: =HYPERLINK("https://simpinc.com","simpinc.com") -> simpinc.com | D34: Lafayette / Westminster | E34: 1993 | F34: =IF(E34="","",Method!$B$2-E34) -> 33 | G34: 10 | H34: 25 | I34: Manages 1,000+ endpoints; headcount not disclosed | J34: =IF(G34="","",ROUND(G34*Method!$B$3/1000000,1)) -> 1.5 | K34: =IF(H34="","",ROUND(H34*Method!$B$4/1000000,1)) -> 5 | L34: =IF(J34="","",ROUND(J34*Method!$B$6*Method!$B$7,1)) -> 0.9 | M34: =IF(K34="","",ROUND(K34*Method!$B$6*Method!$B$8,1)) -> 5.3 | O34: Independent; founder status of current CEO UNVERIFIED | P34: Ryan Rolfsmeier (CEO) — whether he is the 1993 founder is NOT established | Q34: Verify | R34: OLDEST founding date in the entire Colorado dataset (1993) IF Rolfsmeier is the original founder — key gap to close | T34: General MSP; support/maintenance, consulting, data protection; targets 10-50 user SMBs | V34: Serves Fort Collins/Greeley/Loveland/Longmont/Lafayette/Westminster via service-area pages
A35: C | B35: TruTech IT Solutions | C35: =HYPERLINK("https://www.trutechit.com","www.trutechit.com") -> www.trutechit.com | D35: Colorado Springs (+ Pueblo, Denver, Central FL) | E35: 2010 | F35: =IF(E35="","",Method!$B$2-E35) -> 16 | G35: 10 | H35: 20 | I35: Unverified | J35: =IF(G35="","",ROUND(G35*Method!$B$3/1000000,1)) -> 1.5 | K35: =IF(H35="","",ROUND(H35*Method!$B$4/1000000,1)) -> 4 | L35: =IF(J35="","",ROUND(J35*Method!$B$6*Method!$B$7,1)) -> 0.9 | M35: =IF(K35="","",ROUND(K35*Method!$B$6*Method!$B$8,1)) -> 4.2 | O35: Appears independent | P35: Not disclosed | Q35: Verify | R35: No signal found | T35: Managed IT (fixed monthly, unlimited support model), M365, cloud backup, network/email security | V35: Unusual dual-state CO/FL footprint for a firm this size
A36: C | B36: Stepping Forward Technology | C36: =HYPERLINK("https://steppingforward.tech","steppingforward.tech") -> steppingforward.tech | D36: Colorado Springs | E36: 2006 | F36: =IF(E36="","",Method!$B$2-E36) -> 20 | G36: 10 | H36: 12 | I36: Datanyze 10; RocketReach 12 | J36: =IF(G36="","",ROUND(G36*Method!$B$3/1000000,1)) -> 1.5 | K36: =IF(H36="","",ROUND(H36*Method!$B$4/1000000,1)) -> 2.4 | L36: =IF(J36="","",ROUND(J36*Method!$B$6*Method!$B$7,1)) -> 0.9 | M36: =IF(K36="","",ROUND(K36*Method!$B$6*Method!$B$8,1)) -> 2.5 | O36: Owner-operated, husband-and-wife | P36: Matthew Harvey (CEO) & Jennifer Harvey (Co-Owner) | Q36: Verify | R36: No signal found | T36: Managed IT, strategic IT consulting, cybersecurity, cloud, compliance support
A37: C | B37: CTI Corporate Technologies, Inc. | D37: Pueblo | E37: 2003 | F37: =IF(E37="","",Method!$B$2-E37) -> 23 | G37: 5 | H37: 15 | I37: Unverified | J37: =IF(G37="","",ROUND(G37*Method!$B$3/1000000,1)) -> 0.8 | K37: =IF(H37="","",ROUND(H37*Method!$B$4/1000000,1)) -> 3 | L37: =IF(J37="","",ROUND(J37*Method!$B$6*Method!$B$7,1)) -> 0.5 | M37: =IF(K37="","",ROUND(K37*Method!$B$6*Method!$B$8,1)) -> 3.2 | O37: Veteran-owned small business | P37: Not disclosed | Q37: Verify | R37: No signal found — but the ONLY genuinely Pueblo-HQ'd MSP identified in a city of ~110K, i.e. an incumbent with almost no local competition | T37: Small business IT support/consulting/sales, network hosting/shared data center, backup | U37: 90%+ positive (source unclear, low confidence) | V37: Founding year conflicts (1990 vs 2003); website did not reliably resolve — verify directly
A38: C | B38: TriOptimum Technologies | C38: =HYPERLINK("https://www.trioptech.com","www.trioptech.com") -> www.trioptech.com | D38: Montrose | G38: 3 | H38: 5 | I38: Only 2 principals named — likely at or below size floor | J38: =IF(G38="","",ROUND(G38*Method!$B$3/1000000,1)) -> 0.5 | K38: =IF(H38="","",ROUND(H38*Method!$B$4/1000000,1)) -> 1 | L38: =IF(J38="","",ROUND(J38*Method!$B$6*Method!$B$7,1)) -> 0.3 | M38: =IF(K38="","",ROUND(K38*Method!$B$6*Method!$B$8,1)) -> 1.1 | O38: Not disclosed | P38: Chris Parker & David Turner (key personnel) | Q38: Verify | R38: No signal found | T38: Managed IT — proactive monitoring, helpdesk, endpoint security, backups; strong municipal/utility client orientation for a small firm | V38: Verify headcount before outreach
A39: C | B39: Kosh Solutions | C39: =HYPERLINK("https://www.koshsolutions.com","www.koshsolutions.com") -> www.koshsolutions.com | D39: Durango branch (HQ Las Cruces, NM) | E39: 2005 | F39: =IF(E39="","",Method!$B$2-E39) -> 21 | G39: 10 | H39: 25 | I39: Unverified — multi-state firm, CO-only share unknown | J39: =IF(G39="","",ROUND(G39*Method!$B$3/1000000,1)) -> 1.5 | K39: =IF(H39="","",ROUND(H39*Method!$B$4/1000000,1)) -> 5 | L39: =IF(J39="","",ROUND(J39*Method!$B$6*Method!$B$7,1)) -> 0.9 | M39: =IF(K39="","",ROUND(K39*Method!$B$6*Method!$B$8,1)) -> 5.3 | O39: Private — no PE sponsor found | P39: Koert Council & Joshua Fristoe (cofounders); Travis Alsup (CEO since 2012, non-founder) | Q39: Verify | R39: Non-founder professional CEO installed 2012 while both cofounders remain associated — a pattern that often precedes a sale, though no stated intent found | T39: Managed IT/network, M365, hardware rental, BCDR, CMMC compliance — explicit DIB relevance given Four Corners federal footprint | V39: 2026 MSP 501 honoree; Durango is a real staffed branch, not HQ
A40: X | B40: NexusTek | C40: =HYPERLINK("https://www.nexustek.com","www.nexustek.com") -> www.nexustek.com | D40: Greenwood Village | E40: 1996 | F40: =IF(E40="","",Method!$B$2-E40) -> 30 | G40: 250 | H40: 750 | I40: Clutch band 250-999 | J40: =IF(G40="","",ROUND(G40*Method!$B$3/1000000,1)) -> 37.5 | K40: =IF(H40="","",ROUND(H40*Method!$B$4/1000000,1)) -> 150 | L40: =IF(J40="","",ROUND(J40*Method!$B$6*Method!$B$7,1)) -> 22.5 | M40: =IF(K40="","",ROUND(K40*Method!$B$6*Method!$B$8,1)) -> 157.5 | O40: ACQUIRED — ABRY Partners (with Alvarez & Marsal Capital), Dec 13 2017, from Lightview Capital; later merged with Breakthrough Technology Group | P40: PE-controlled; no founder-owner remains | Q40: N/A | R40: ABRY has held since 2017 (9 yrs) — beyond a typical 5-7yr PE hold, an exit may be due | T40: National MSP for SMB — managed cloud, cybersecurity, business continuity; Channel Futures MSP 501, 3x CRN Triple Crown | U40: 4.2 (6 Clutch) | V40: Itself an acquirer (bought ICCS & Co)
...

Sheet Small Shops (Roll-up)
A1: Roll-up potential | B1: Company | C1: Website | D1: City | E1: Owner / principal | F1: Founded | G1: Est. staff | H1: Service mix (recurring vs break-fix) | I1: Client base | J1: Owner tenure / age signal (inference) | K1: Rationale | L1: Notes / status
A2: High | B2: Ariel IT Services (arielMIS) | C2: =HYPERLINK("https://arielitservices.com","arielitservices.com") -> arielitservices.com | D2: Louisville | E2: 2010 | F2: 2-10 (est.) | G2: RECURRING MSP model — explicitly shifted from break-fix, 'one of the first in the area'; predecessor lineage to 1996 | H2: Bob McCool (owner; bought out 1996 co-founder; merged w/ Cam Marshall's Marshall Information Service 2006) | I2: B2B and nonprofits, Denver/Boulder/Longmont area | J2: 30-year lineage (1996-2026); owner ALREADY EXECUTED one M&A move (2006 merger) — sophisticated, deal-experienced, plausible seller | K2: Oldest lineage found in Colorado; deliberate early MSP-model adopter with prior M&A experience — strongest tuck-in candidate on this tab
A3: High | B3: TekMyBiz | C3: =HYPERLINK("https://tekmybiz.com","tekmybiz.com") -> tekmybiz.com | D3: Colorado Springs | E3: 1993 | F3: ~11 (ZoomInfo) | G3: RECURRING — cybersecurity/compliance, cloud, backup, managed IT, security cameras, VoIP, staff aug | H3: Mike Molsen (CEO/founder) | I3: SMB, Colorado Springs + Elk Grove Village IL | J3: 32-year founder tenure (1993-2026) — the STRONGEST age/tenure signal found across all of Colorado | K3: Longest-tenured founder found; real recurring B2B book; strong review volume/rating; multi-state ops = real infrastructure not a solo shop | L3: 4.9 (32 Google); 5.0 (26 TrustAnalytica)
A4: High | B4: Windward Networks | C4: =HYPERLINK("https://windwardnetworks.com","windwardnetworks.com") -> windwardnetworks.com | D4: Boulder (+ Longmont) | E4: 2004 | F4: 5 (ZoomInfo) | G4: RECURRING MSP — IT security, network upgrades, virtualization, data protection; real estate/healthcare/law verticals | H4: Kelly Garrison (Partner) | I4: B2B, Boulder/Longmont, compliance-heavy verticals | J4: 22 years operating; ~$4M revenue on 5 employees is a NOTABLY HIGH revenue-per-head ratio — strong signal of high-margin recurring revenue, not commodity break-fix | K4: Right-sized headcount, long tenure, vertical specialization, unusually strong rev/headcount ratio — one of the strongest candidates found
A5: Medium-High | B5: InfiNet Computer Solutions | C5: =HYPERLINK("https://infinetinc.com","infinetinc.com") -> infinetinc.com | D5: Fort Collins | E5: 1998 | F5: Unknown — 'same ownership since 1998' | G5: RECURRING — managed IT, cybersecurity, hosting for small businesses | H5: Tad Osborn (President) | I5: B2B, Northern Colorado | J5: 28 years, SAME OWNERSHIP throughout — strong tenure signal | K5: Very long stable single-owner tenure is a strong exit-readiness signal; headcount needs direct verification
A6: Medium-High | B6: Code Blue Computing, Inc. | C6: =HYPERLINK("https://codebluecomputing.com","codebluecomputing.com") -> codebluecomputing.com | D6: Broomfield | E6: 2009 | F6: Unknown — 'under 49' band | G6: RECURRING MSP + cybersecurity for law firms, manufacturing, CPAs | H6: Jeri Morgan (President) & Bill Morgan (Co-Owner) — husband-wife, woman-owned | I6: B2B, Denver/Boulder area, named verticals (legal, mfg, accounting) | J6: 17-year firm, husband-wife ownership — plausible succession/exit candidate given family structure and multi-decade run | K6: Strong review volume (86 Google) and rating, named B2B verticals, family-owned = often correlates with exit openness | L6: A+ BBB; 86 Google; 22 Yelp — 2nd-strongest review volume in this dataset
A7: Medium-High | B7: Netirio | C7: =HYPERLINK("https://netirio.com","netirio.com") -> netirio.com | D7: Denver / Arvada | E7: 2019 | F7: 2-10 (est.) | G7: FULLY RECURRING — managed IT, cybersecurity, cloud migration, help desk, VoIP, BCDR | H7: Avery H. George (CEO) — also previously owned 'Denver Computer Techs' | I7: B2B, Denver metro | J7: Owner claims 15+ years IT experience; ALREADY an active operator/acquirer of a second brand — may be a competitor/consolidator rather than a seller | K7: Strongest review volume in the entire dataset (72 Google, 5.0) is a real positive signal, but verify seller intent before approaching — he may be building, not selling | L7: 5.0 (72 Google) — strongest review volume found
A8: Medium-High | B8: Colorado Information Technologies, Inc. | C8: =HYPERLINK("https://www.coinfotech.com","www.coinfotech.com") -> www.coinfotech.com | D8: Colorado Springs | E8: 1986 (D&B) or ~1995 (other source) — CONFLICTING | F8: 10-20 (D&B) vs. 2 (other source) — CONFLICTING, must resolve before outreach | G8: Network consulting, server/workstation support, managed IT for SMB | H8: Jeremy Higham (owner) | I8: SMB, Colorado Springs | J8: IF the 1986 date is accurate this is a ~40-YEAR firm — an even stronger age signal than TekMyBiz; needs verification given the date conflict | K8: Potentially one of the oldest, most substantial shops found — but the headcount/founding-date conflict must be resolved first
A9: Medium | B9: Firma IT Solutions and Services | C9: =HYPERLINK("http://firmaitss.com","firmaitss.com") -> firmaitss.com | D9: Colorado Springs | E9: Rodney Gullatte, Jr. (USAF veteran, CISSP/CISO/CNDA) | G9: 3-4 (conflicting) | H9: RECURRING MSP + cybersecurity | I9: B2B, Colorado Springs; veteran/minority-owned business network ties | J9: 2019 Pikes Peak Veteran Business Owner of the Year — seasoned, credentialed operator; no clear retirement-age signal | K9: Right-sized headcount, strong ratings (5.0 Angi/HomeAdvisor, A+ BBB), veteran/minority-owned story could matter for buyer diligence | L9: 5.0 (Angi, HomeAdvisor); A+ BBB
A10: Medium | B10: Aspire Technology Solutions | C10: =HYPERLINK("https://www.aspiredenver.com","www.aspiredenver.com") -> www.aspiredenver.com | D10: Wheat Ridge | E10: 2000 | F10: ~11 | G10: RECURRING MSP — network management, data protection, cybersecurity | H10: Zachary 'Zack' Heckler (Founder & President, founded as a college freshman) | I10: B2B Denver-metro; named case studies incl. Boulder Sausage | J10: 26 years running the firm since founding at ~19-20 — founder likely mid-to-late 40s now, plausible succession-stage candidate | K10: Long tenure, real named B2B references; headcount (11) is above strict 1-5 target but relevant as a small-platform candidate
A11: Medium | B11: Pro-IS | C11: =HYPERLINK("https://pro-is.com","pro-is.com") -> pro-is.com | D11: Fort Collins | E11: 1998 | F11: 2-10 | G11: RECURRING — full-service IT support, managed IT, consulting for SMB | H11: Unknown — not identified in any source | I11: B2B SMB, Fort Collins | J11: 28-year-old firm; owner identity unknown so age/tenure can't be inferred | K11: Long tenure and right-sized headcount are attractive, but identifying the principal is the necessary first step
A12: Medium | B12: Northwest Data Services, Inc. | C12: =HYPERLINK("https://northwestdata.com","northwestdata.com") -> northwestdata.com | D12: Steamboat Springs | E12: 1993 | F12: ~11 | G12: MIXED — 'personalized technology solutions for both businesses AND homes'; also structured wiring, fiber, cameras, phones | H12: Bryan Bassett, Jon Quinn (President), Clay Ogden — General Partners | I12: Both business and residential, Steamboat Springs | J12: 33-year-old firm, multi-partner structure — a partnership nearing 3 decades often signals succession planning underway | K12: Very long tenure and multi-partner ownership; residential/consumer component dilutes the pure-B2B thesis; worth outreach to gauge partner succession intent
A13: Medium | B13: Zen Technology Solutions | C13: =HYPERLINK("https://www.zentechnologysolutions.com","www.zentechnologysolutions.com") -> www.zentechnologysolutions.com | D13: Englewood / Greenwood Village | E13: 2018 | F13: 2-3 (conflicting) | G13: FULLY RECURRING — managed firewalls/servers/WiFi, endpoint protection, security assessments, email filtering, awareness training | H13: Joshua 'Josh' Stark (Founder & CEO) | I13: Small offices, Denver-area B2B | J13: 8-year-old firm; founder profile unclear on age/prior career | K13: Genuinely recurring B2B mix is attractive, but very small and young, founder appears still building not exiting
A14: Medium | B14: Comprehensive Computer Consulting (C3) | C14: =HYPERLINK("https://c3direct.net","c3direct.net") -> c3direct.net | D14: Colorado Springs | E14: 2006 | F14: 2-18 (conflicting) | G14: RECURRING — tailored IT solutions, ongoing network infrastructure support | H14: Michael Yopp | I14: B2B SMB, Colorado Springs | J14: 20-year-old firm; owner likely peak-to-late career (inference) | K14: 20-yr tenure and clear B2B positioning are attractive; headcount conflict (2 vs 18) needs resolving before sizing as tuck-in vs. small platform
A15: Medium | B15: GrahamGolden Technologies | C15: =HYPERLINK("https://www.grahamgoldentech.com","www.grahamgoldentech.com") -> www.grahamgoldentech.com | D15: Denver | E15: 2001 | F15: 11-50 (LinkedIn) — larger than target range | G15: RECURRING — server/infrastructure design, project planning, networking, virtualization, VoIP | H15: Ralph Graham & Jeremy Golden (co-founding partners) | I15: B2B Denver | J15: 25 yrs combined; '35 combined years experience' at founding implies an older founder cohort now (50s+ inference) | K15: Too large for a clean 1-5-person tuck-in — more of a small-platform acquisition; worth tracking if mandate flexes upward
A16: Medium | B16: Wavefinity, LLC | C16: =HYPERLINK("https://wavefinity.net","wavefinity.net") -> wavefinity.net | D16: Minturn (Vail Valley/Eagle/Summit/Lake counties) | E16: Nathan Malone | G16: Likely solo/very small | H16: CLEAN RECURRING B2B/MSP — network troubleshooting, cybersecurity hardening, email security, full M365 admin/migration — no consumer-repair language found | I16: Small businesses, resort-corridor geographic moat similar to Roaring Fork Help Desk | J16: 20+ years personal IT career (inference); company/entity age unconfirmed | K16: Clean recurring model, valuable mountain-resort geographic moat, but single-operator concentration risk is high
A17: Medium | B17: DCM Technology Solutions | D17: Parker (HQ originally Illinois) | E17: Leslie A. Kleyweg; Adam Kleyweg, Denis Casarotto (family-run signal) | F17: 2001 | G17: 2-8 (conflicting) | H17: Unclear — service mix not detailed in available sources; needs direct verification | I17: Unknown/not detailed | J17: 23-25 years; Kleyweg family names suggest multi-generational/family ownership — positive succession signal | K17: Long tenure and apparent family ownership are attractive but service mix and client base unverified
A18: Medium | B18: EnTech IT Solutions | C18: =HYPERLINK("https://www.entechitsolutions.com","www.entechitsolutions.com") -> www.entechitsolutions.com | D18: Littleton | E18: 2010 | F18: 2-9 | G18: RECURRING — managed IT, cybersecurity, VoIP, data backup, cloud computing, IT consulting | H18: Bryan Evege (President & Founder) | I18: Small businesses, greater Denver area | J18: 16 years running the firm; prior career as Network Engineer at an MVNO — age unknown | K18: Solid recurring model and 16-year tenure are positives, but thin review count and unverified headcount limit confidence | L18: 5.0 (1 review — thin sample)
A19: Medium | B19: Imperitiv Solutions LLC | C19: =HYPERLINK("https://imperitiv.com","imperitiv.com") -> imperitiv.com | D19: Denver (also Castle Rock) | E19: 2015 | F19: 2-9 | G19: Managed IT support, cybersecurity, CMMC compliance, cloud — leans federal-contractor-adjacent | H19: Jeff Rash (Senior Principal Consultant, Castle Rock-based) | I19: SMBs, some federal-contractor/compliance work | J19: ~20 yrs career experience (Raytheon, Cisco, Virtela background) — age unknown | K19: CMMC/compliance specialization is valuable but thin review count (9 Google) suggests a small book | L19: 5.0 (9 Google)
A20: Medium | B20: PR27:2 Managed IT Services | C20: =HYPERLINK("https://www.pr272managedit.com","www.pr272managedit.com") -> www.pr272managedit.com | D20: Loveland | E20: 2009 (as ACTS LLC) / 2022 (current entity) | F20: 2-10 | G20: RECURRING today, but ORIGIN as home-user support (residential legacy tail possible) | H20: 'Jeff' (CEO, CISSP/CISA — surname not found) | I20: B2B (current positioning), Loveland/Fort Collins | J20: '25+ years experience' claimed (unverified); murky entity history (ACTS LLC -> partnership 2022) complicates true-age assessment | K20: Legitimate B2B positioning today with a credentialed owner, but needs diligence to separate the 17-yr operating narrative from the 4-yr legal entity fact
A21: Medium | B21: Summit Net Trekker LLC | C21: =HYPERLINK("https://computerservicebreckenridge.com","computerservicebreckenridge.com") -> computerservicebreckenridge.com | D21: Breckenridge | E21: 2001 | F21: Small — no hard number | G21: MIXED — small-business IT consulting/MSP PLUS data recovery and laptop repair | H21: Daniel 'Bud' Robinson III | I21: Small businesses, Breckenridge/Summit County | J21: 25-year-old company — strong tenure signal, age unknown | K21: Long tenure is a positive, but consumer-repair mix dilutes the recurring-revenue thesis; verify % contract vs. one-off repair
A22: Medium | B22: Roaring Fork Help Desk, Inc. | C22: =HYPERLINK("https://rfhelpdesk.net","rfhelpdesk.net") -> rfhelpdesk.net | D22: Glenwood Springs | E22: 2006 (site) or 2015 (LinkedIn) — CONFLICTING | F22: 2-10 | G22: MIXED — help desk/MSP work PLUS 'computer repair and virus removal' consumer-adjacent language | H22: Matthew McBrayer (President/Founder) | I22: Aspen, Snowmass Village, Basalt, Carbondale, Glenwood Springs — affluent resort-corridor SMBs and individuals | J22: 15+ yrs IT experience (inference); also hosts a local radio tech show — community fixture | K22: Family-run, long local roots in an affluent resort market, but consumer-repair blend and founding-date conflict need resolving
A23: Medium | B23: OliveTech LLC | C23: =HYPERLINK("https://olive.tech","olive.tech") -> olive.tech | D23: Berthoud | E23: 2021 | F23: Very small — residential address | G23: Managed IT + cybersecurity for professional-services firms; also agriculture/livestock IT | H23: Todd Hebebrand (also co-owns 'Berthoud IT') | I23: B2B, Fort Collins/Loveland/Berthoud/Northern CO | J23: Prior co-owner of 'Onix IT'; career-experienced but this entity is only ~5 years old | K23: Real B2B recurring book but very young entity, and owner appears to run a parallel venture — unclear which is the primary book
A24: Low-Medium | B24: TriOptimum Technologies | C24: =HYPERLINK("https://www.trioptech.com","www.trioptech.com") -> www.trioptech.com | D24: Montrose | E24: Christopher Thomas Parker (Owner) & David Turner (Technical Director) | F24: 2020 | G24: 2-5 (est.) | H24: MSP — 'business class computer and network support', positioned as recurring managed services | I24: B2B, Western Slope | J24: 5-year-old firm; Parker is a career Army aviation officer transitioning into IT (2nd-career founder, still studying) — growth mode not exit mode | K24: Right model and geographic moat, but too young and founder profile suggests growth, not a retirement-window exit
A25: Low | B25: Ramdyne Technology LLC | C25: =HYPERLINK("https://www.ramdyne.com","www.ramdyne.com") -> www.ramdyne.com | D25: Fort Collins | E25: 2007 | F25: 1 (ZoomInfo/D&B, ~$192K rev) | G25: Managed/recurring — network security, backup/recovery, hosted Exchange, remote support, phones | H25: Phil McNeal | I25: SMB, Fort Collins/Loveland/Greeley/Windsor | J25: 19 years running the firm — age unknown | K25: Genuine recurring book but severe key-person risk at headcount 1; verify book size before pursuing
A26: Low | B26: Integrity Technologies | C26: =HYPERLINK("https://integtech.net","integtech.net") -> integtech.net | D26: Fort Collins | E26: 2016 | F26: 2-10 | G26: Strongly recurring — help desk, cybersecurity, cloud, compliance; CPA/legal/wealth-mgmt/medical verticals | H26: Unknown | I26: B2B, vertical-specialized (compliance-heavy) | J26: 10-year-old firm, owner unidentified | K26: Strong vertical MSP model but owner unidentified and company relatively young — needs direct outreach to confirm exit readiness
A27: Low | B27: MDL Consulting Inc. | C27: =HYPERLINK("https://mdlconsultinginc.net","mdlconsultinginc.net") -> mdlconsultinginc.net | D27: Silverthorne (Summit County) | E27: 2001 | F27: 8 | G27: PRIMARILY consumer/residential repair — 'family owned and operated computer repair company' | H27: Family-owned; individual name not confirmed | I27: Mountain communities (Breckenridge, Copper, Dillon, Frisco, Keystone, Silverthorne) | J27: 25-year-old firm | K27: Consumer-repair framing despite long tenure and decent headcount — likely thin or nonexistent recurring book
A28: Low | B28: Colorado Computers | C28: =HYPERLINK("https://coloradocomputers.net","coloradocomputers.net") -> coloradocomputers.net | D28: South Denver / Parker / Castle Rock / Highlands Ranch | E28: 1997 | F28: Unknown — small/near-solo | G28: EXPLICITLY consumer/residential-leaning — on-site/in-home repair, virus removal, data recovery, training | H28: Charlie Dunham (Electrical Engineer by training) | I28: Mixed SMB and consumer | J28: 29-year owner-operator — one of the longest tenures found, but service mix is consumer-repair-dominated | K28: Very long tenure (attractive signal) undercut by consumer-repair-dominated marketing — treat as low priority unless outreach reveals an unadvertised B2B book
A29: Low | B29: Simply Tech | C29: =HYPERLINK("https://www.simplytechdenver.com","www.simplytechdenver.com") -> www.simplytechdenver.com | D29: Castle Rock | E29: 2017 | F29: Unknown — very small | G29: EXPLICITLY consumer/residential repair — 'on-site and takeaway based computer and tech repair' | H29: Unknown | I29: Mixed individual/consumer and small business | J29: 9-year-old firm, owner unidentified | K29: Consumer-repair business model, too young, owner unidentified — poor tuck-in fit
A30: Low | B30: My Computer Guy LLC | C30: =HYPERLINK("https://mycoloradocomputerguy.com","mycoloradocomputerguy.com") -> mycoloradocomputerguy.com | D30: Colorado Springs | E30: 2010 | F30: Unknown — solo/very small | G30: Branding signals consumer/residential and handyman-IT positioning — hardware, low-voltage/security installs, cloud | H30: Lenny Griffin | I30: Unclear, likely mixed consumer/small business | J30: 16 years as this entity; owner claims 20+ yrs personal career | K30: 'Computer guy' consumer-facing model rather than recurring B2B managed-services book — low roll-up value despite reasonable tenure
A31: Medium | B31: SpeedWise IT Services | C31: =HYPERLINK("https://speedwise.net","speedwise.net") -> speedwise.net | D31: Northglenn | E31: 2004 | F31: 2-3 (BBB) — at or below size floor | G31: RECURRING — VoIP, managed IT, IT consulting, cybersecurity, cloud migration | H31: Eric Frickell (owner) | I31: Small businesses, Northglenn/Denver metro | J31: 22-year operating history, single small owner — classic small lifestyle-business profile | K31: Very small but 22-yr locally-owned BBB A+ history is a plausible cheap tuck-in despite marginal size | L31: BBB A+; genuine local HQ, not a satellite office
A32: Medium | B32: Waypoint Technology Solutions | C32: =HYPERLINK("https://thinkwaypoint.com","thinkwaypoint.com") -> thinkwaypoint.com | D32: Erie | E32: 2011 | F32: 5-9 (ZoomInfo) | G32: Help desk, network/server/cloud, cybersecurity, IT project consulting — appears B2B | H32: Not identified in this pass | I32: Colorado Front Range and beyond (unspecified) | J32: 14 years operating with near-ZERO review/marketing footprint (0 reviews on Facebook and Birdeye) — inference of a steady-state, low-growth lifestyle business | K32: Genuine local Erie HQ (rare in this pass — most 'Erie' results were satellite/national); thin marketing footprint is itself a soft signal worth a direct call | L32: 0 reviews found despite 14 yrs — verify this is not a wind-down
A33: Low-Medium | B33: ITGuys (mynewitguys.com) | C33: =HYPERLINK("https://mynewitguys.com","mynewitguys.com") -> mynewitguys.com | D33: Denver / Lakewood | E33: 2009 | F33: 11-50 (ZoomInfo) — may exceed tuck-in range | G33: Managed IT, on-site computer support for small businesses; notable community angle (refurbishes recycled laptops for donation) | H33: Not identified in this pass | I33: Small businesses; serves Westminster via dedicated page | J33: 17 years operating; owner unidentified | K33: Real MSP with a positive community story, but conflicting HQ claims (downtown Denver vs. Lakewood) and unidentified owner need resolving first
A34: Low-Medium | B34: Workplace IT | C34: =HYPERLINK("https://workplaceit.net","workplaceit.net") -> workplaceit.net | D34: Arvada / Denver (HQ conflicting across own sourcing) | E34: 2016 | F34: 2 (one aggregator) — very small | G34: Managed IT, cybersecurity, IT compliance (CMMC/ITAR/FISMA/FINRA), VoIP, cloud, structured cabling | H34: Jason Canon (per aggregator; unverified) | I34: Front Range Fort Collins-to-Castle Rock (claimed) | J34: Site claims '10+ years in Denver' which conflicts with a 2016 founding date — unresolved discrepancy | K34: Real compliance-forward service mix, but HQ location and founding date both internally inconsistent — verify directly before any outreach | L34: 4.7 (14 Google, per a competitor citation — secondary source)
A36: Micro tuck-in pricing (from 2025-26 market benchmarks - see Acquirers tab):
A37: Sub-$1M revenue: 3.0-5.0x SDE. Contracted-MRR micro-MSPs price toward the top of that band; consumer/break-fix books toward the bottom. Typical structure: 65-85% cash at close, 5-15% seller note (Prime+2-4%, often PIK), 5-20% earnout tied to MRR retention over 12-24 months.
A38: Colorado's micro-market is thinner than the Triangle's but shows real activity: Networks Unlimited (Grand Junction) bought 307 Tech Pros in Casper WY (Sep 2025), and it is itself a plausible buyer for Western Slope micro-books. No confirmed acquisition of a Denver-metro or Colorado Springs micro-shop (<10 staff) was found in this pass - that segment appears genuinely under-consolidated.
A39: NOTE: this tab draws on a targeted 30-shop sweep plus a separate Boulder-focused enrichment pass - check the file date/version for the latest state. Colorado has hundreds of micro IT shops statewide; this is a sample, not an exhaustive census.

Sheet Acquirers
A1: Acquirer | B1: HQ | C1: Website | D1: Type | E1: Ownership / sponsor | F1: Colorado deals (date) | G1: Wider footprint & recent deals | H1: Appetite / criteria | I1: Actively acquiring?
